Workbook

Sheet Perguntas
A2: 1. Possui algum equipamento de energia térmica nas suas instalações? | D2: Sim | E2: Não | G2: Caso não possuam equipamentos acaba.
A4: 2. Tem conhecimento dos consumos anuais de cada vetor energético por equipamento ou apenas os globais? | L4: Equipamento | N4: Global | Q4: 3.1 Selecione os vetores energéticos usados nas susas instalações e correspondente consumo anual.
R6: 3.2 Selecione os equipamentos existentes e respetiva potência nominal bem como a eficiência de catálogo e o vetor energético consumido.
B7: 2.1. Selecione os equipamentos existentes e respetiva potência nominal bem como a eficiência de catálogo, vetor energético e consumo anual.
S8: 3.3 Já é efetuada a recuperação de calor residual dos processos industriais? (Pergunta específica a cada um dos equipamentos indicados) | AA8: Não | AB8: Sim
C9: 2.2. Já é efetuada a recuperação de calor residual dos processos industriais? | K9: Não | L9: Sim
T10: 3.4 Indique a temperatura e caudal dos gases de exaustão. | AB10: Caso já procedam à recuperação de calor residual acaba.
D11: 2.3. Indique a temperatura e caudal dos gases de exaustão. | L11: Caso já procedam à recuperação de calor residual acaba.
A14: 4. Tem conhecimento da tarifa associada a cada um dos vetores energéticos consumidos? | F14: Sim | G14: Não | I14: Caso não saiba as tarifas associadas é usada a base de dados.
B16: 4.1 | C16: Indique, por vetor energético, a tarifa de referência.

Sheet Inputs
A4: Consumo por equipamento ou fábrica | B4: Consumo por fábrica
A7: Caso seja consumo por equipamento
A8: Equipamento | B8: Potência Nominal [kW] | C8: Eficiência de catálogo [%] | D8: Combustível | E8: Consumo anual por equipamento [unidade/ano] | F8: (Unidade/ano) | G8: Sistema de recuperação térmica | H8: =+IF(G9="Sim","","Temperatura de gases de exaustão [°C]") -> Temperatura de gases de exaustão [°C] | I8: =+IF(G9="Sim","","Caudal de gases de exaustão [m3/h]") -> Caudal de gases de exaustão [m3/h]
A9: Forno | B9: 100 | C9: 80 | D9: Gás Natural | E9: 5000 | F9: m3/ano | G9: Não | H9: 150 | I9: 2000
A10: Caldeira | B10: 150 | C10: 80 | D10: GPL | E10: 30000 | F10: m3/ano | G10: Não | H10: 200 | I10: 3000
A11: Cogeração | B11: 200 | C11: 80 | D11: Gás Natural | E11: 60000 | F11: kWh/ano | G11: Não | H11: 250 | I11: 1000
A12: Queimador (Dedicado a estufas ou banhos térmicos) | B12: 60 | C12: 80 | D12: Gás Natural | E12: 20 | F12: kWh/ano | G12: Não
F13: kWh/ano | G13: Não
A14: (…)
A17: Caso seja consumo por fábrica
A18: Combustível | B18: Consumo por fábrica [unidade/ano] | C18: (Unidade/ano)
A19: Gás Natural | B19: 30000 | C19: kWh/ano
A22: (…)
A25: Equipamento | B25: Potência Nominal [kW] | C25: Combustível | D25: Eficiência de catálogo [%] | E25: Número de horas de funcionamento | F25: Sistema de recuperação térmica | G25: =+IF(F26="Sim","","Temperatura de gases de exaustão [°C]") | H25: =+IF(F26="Sim","","Caudal de gases de exaustão [m3/h]")
A26: Caldeira | B26: 350 | C26: Gás Natural | D26: 85 | F26: Sim | G26: 150 | H26: 2000
A27: Forno | B27: 500 | C27: Gás Natural | D27: 82.5 | F27: Sim | G27: 200 | H27: 3000
A28: Cogeração | B28: 0 | C28: Gás Natural | D28: 80 | F28: Sim
A29: Queimador (Dedicado a estufas ou banhos térmicos) | B29: 0 | C29: Gás Natural | D29: 80 | F29: Sim
A30: (…)
A33: Definição de tarifas
A34: Tem conhecimento da tarifa associada a cada um dos vetores energéticos? | B34: Sim
A35: Vetor energético | B35: Tarifa referência | C35: Unidade
A36: Gás Natural | B36: 0.078 | C36: €/kWh
A37: GPL | C37: €/kWh
A38: GPL | C38: €/kWh
A39: Gás Natural | C39: €/kWh
A40: (…)

Sheet Processamento
B2: Cálculos auxiliares | AH2: Cálculos auxiliares caso apenas seja conhecido o consumo por fábrica
B4: Potencial de descarbonização (Potencial alteração de vetor energético) | M4: Potencial descarbonização - recuperação de calor | AH4: Potencial de descarbonização (Potencial alteração de vetor energético)
B5: Equipamento | C5: Combustível | D5: Rendimento (%) | E5: Fator Emissão (kgCO2e/kWh) | F5: Consumo kWh/ano | G5: Emissões Kg CO2eq | H5: Conversão tarifa de energia (€/kWh) | I5: Custo de energia (€/ano) | M5: Cp gases de exaustão | N5: 1.04 | O5: kJ/kg.K | AT5: Cp gases de exaustão | AU5: 1.04 | AV5: kJ/kg.K
B6: =+Inputs!A9 -> Forno | C6: =+Inputs!D9 -> Gás Natural | D6: =+Inputs!C9 -> 80 | E6: =VLOOKUP(C6,Apoio!L6:T19,9,FALSE) -> 0.2030472 | F6: =INDEX(Apoio!$P$6:$R$19,MATCH(C6,Apoio!$L$6:$L$19,0),MATCH(Inputs!F9,Apoio!$P$4:$R$4,0))*Inputs!E9 -> 52500 | G6: =VLOOKUP(C6,Apoio!$L$6:$T$19,9,FALSE)*F6 -> 10659.978 | H6: =1/INDEX(Apoio!$P$6:$R$19,MATCH(C6,Apoio!$L$6:$L$19,0),MATCH(VLOOKUP(C6,Inputs!$A$36:$C$39,3,FALSE),Apoio!$P$5:$R$5,0))*VLOOKUP(C6,Inputs!$A$36:$C$39,2,FALSE) -> 0.078 | I6: =IF(Inputs!$B$34="Sim",H6*F6,VLOOKUP(C6,Apoio!$L$6:$U$19,10,FALSE)*F6) -> 4095 | M6: Temperatura mínima | N6: 120 | O6: °C | AH6: Vetor energético | AI6: Consumo fábrica | AJ6: Unidades | AK6: Consumo (kWh/ano) | AT6: Temperatura mínima | AU6: 120 | AV6: °C
B7: =+Inputs!A10 -> Caldeira | C7: =+Inputs!D10 -> GPL | D7: =+Inputs!C10 -> 80 | E7: =VLOOKUP(C7,Apoio!L7:T20,9,FALSE) -> 0.22717764 | F7: =INDEX(Apoio!$P$6:$R$19,MATCH(C7,Apoio!$L$6:$L$19,0),MATCH(Inputs!F10,Apoio!$P$4:$R$4,0))*Inputs!E10 -> 939600 | G7: =VLOOKUP(C7,Apoio!$L$6:$T$19,9,FALSE)*F7 -> 213456.11 | H7: =1/INDEX(Apoio!$P$6:$R$19,MATCH(C7,Apoio!$L$6:$L$19,0),MATCH(VLOOKUP(C7,Inputs!$A$36:$C$39,3,FALSE),Apoio!$P$5:$R$5,0))*VLOOKUP(C7,Inputs!$A$36:$C$39,2,FALSE) -> 0 | I7: =IF(Inputs!$B$34="Sim",H7*F7,VLOOKUP(C7,Apoio!$L$6:$U$19,10,FALSE)*F7) -> 0 | AH7: =+Inputs!C26 -> Gás Natural | AI7: =+Inputs!B19 -> 30000 | AJ7: =+Inputs!C19 -> kWh/ano | AK7: =INDEX(Apoio!$P$6:$R$19,MATCH(AH7,Apoio!$L$6:$L$19,0),MATCH(Inputs!C19,Apoio!$P$4:$R$4,0))*Inputs!B19 -> 30000
B8: =+Inputs!A11 -> Cogeração | C8: =+Inputs!D11 -> Gás Natural | D8: =+Inputs!C11 -> 80 | E8: =VLOOKUP(C8,Apoio!L9:T21,9,FALSE) -> 0.2030472 | F8: =INDEX(Apoio!$P$6:$R$19,MATCH(C8,Apoio!$L$6:$L$19,0),MATCH(Inputs!F11,Apoio!$P$4:$R$4,0))*Inputs!E11 -> 60000 | G8: =VLOOKUP(C8,Apoio!$L$6:$T$19,9,FALSE)*F8 -> 12182.832 | H8: =1/INDEX(Apoio!$P$6:$R$19,MATCH(C8,Apoio!$L$6:$L$19,0),MATCH(VLOOKUP(C8,Inputs!$A$36:$C$39,3,FALSE),Apoio!$P$5:$R$5,0))*VLOOKUP(C8,Inputs!$A$36:$C$39,2,FALSE) -> 0.078 | I8: =IF(Inputs!$B$34="Sim",H8*F8,VLOOKUP(C8,Apoio!$L$6:$U$19,10,FALSE)*F8) -> 4680 | AH8: =+Inputs!C27 -> Gás Natural | AI8: =+Inputs!B20 -> 0 | AJ8: =+Inputs!C20 -> 0 | AK8: =INDEX(Apoio!$P$6:$R$19,MATCH(AH8,Apoio!$L$6:$L$19,0),MATCH(Inputs!C20,Apoio!$P$4:$R$4,0))*Inputs!B20 -> #N/A
B9: =+Inputs!A12 -> Queimador (Dedicado a estufas ou banhos térmicos) | C9: =+Inputs!D12 -> Gás Natural | D9: =+Inputs!C12 -> 80 | E9: =VLOOKUP(C9,Apoio!L11:T22,9,FALSE) -> 0.2030472 | F9: =INDEX(Apoio!$P$6:$R$19,MATCH(C9,Apoio!$L$6:$L$19,0),MATCH(Inputs!F12,Apoio!$P$4:$R$4,0))*Inputs!E12 -> 20 | G9: =VLOOKUP(C9,Apoio!$L$6:$T$19,9,FALSE)*F9 -> 4.060944 | H9: =1/INDEX(Apoio!$P$6:$R$19,MATCH(C9,Apoio!$L$6:$L$19,0),MATCH(VLOOKUP(C9,Inputs!$A$36:$C$39,3,FALSE),Apoio!$P$5:$R$5,0))*VLOOKUP(C9,Inputs!$A$36:$C$39,2,FALSE) -> 0.078 | I9: =IF(Inputs!$B$34="Sim",H9*F9,VLOOKUP(C9,Apoio!$L$6:$U$19,10,FALSE)*F9) -> 1.56 | AH9: (…)
B10: (…)
B11: Cenários para cada equipamento | M11: Equipamento | N11: Potência Nominal [kW] | O11: Eficiência de catálogo [%] | P11: Combustível | Q11: Consumo anual [unidade/ano] | R11: (Unidade/ano) | S11: Temperatura de gases de exaustão [°C] | T11: Caudal de gases de exaustão [m3/h] | U11: Massa volúmica dos gases [kg/m3] | V11: Potência possível de ser recuperada (kW) | W11: Potência possível de ser recuperada (kW) | X11: Horas de funcionamento anuais | Y11: Energia anual possivel de recuperar (kWh) | Z11: Preponderância no consumo total da fábrica | AA11: Redução de emissões de GEE (kg CO2/ano) | AB11: Poupança económica | AT11: Equipamento | AU11: Potência Nominal [kW] | AV11: Eficiência de catálogo [%] | AW11: Combustível | AX11: Consumo anual [kWh/ano] | AY11: Temperatura de gases de exaustão [°C] | AZ11: Caudal de gases de exaustão [m3/h] | BA11: Massa volúmica dos gases [kg/m3] | BB11: Potência possível de ser recuperada (kW) | BC11: Potência possível de ser recuperada (kW) | BD11: Horas de funcionamento anuais | BE11: Energia anual possivel de recuperar (kWh) | BF11: Preponderância no consumo total da fábrica | BG11: Redução de emissões de GEE (kg CO2/ano) | BH11: Poupança económica
M12: =+Inputs!A9 -> Forno | N12: =+Inputs!B9 -> 100 | O12: =+Inputs!C9 -> 80 | P12: =+Inputs!D9 -> Gás Natural | Q12: =+Inputs!E9 -> 5000 | R12: =+Inputs!F9 -> m3/ano | S12: =+Inputs!H9 -> 150 | T12: =+Inputs!I9 -> 2000 | U12: =+(101325*(28.96/1000))/(8.314*(S12+273.15)) -> 0.83408595 | V12: =+T12/3600*U12*$N$5*(S12-$N$6) -> 14.45749 | W12: =+V12*0.7 -> 10.120243 | X12: 6000 | Y12: =X12*W12 -> 60721.457 | Z12: =+Y12/SUM($F$6:$F$9) -> 0.057713433 | AA12: =VLOOKUP(P12,Apoio!L6:T19,9,FALSE)*Y12 -> 12329.322 | AB12: =+Y12*VLOOKUP(P12,Apoio!$L$6:$U$19,10,FALSE) -> 4705.9129 | AT12: =+Inputs!A26 -> Caldeira | AU12: =+Inputs!B9 -> 100 | AV12: =+Inputs!D26 -> 85 | AW12: =VLOOKUP(AT12,Inputs!A26:H29,3,FALSE) -> Gás Natural | AX12: =+AM14 -> 12352.941 | AY12: =+Inputs!G26 -> 150 | AZ12: =+Inputs!H26 -> 2000 | BA12: =+(101325*(28.96/1000))/(8.314*(AY12+273.15)) -> 0.83408595 | BB12: =+AZ12/3600*BA12*$AU$5*(AY12-$AU$6) -> 14.45749 | BC12: =+BB12*0.7 -> 10.120243 | BD12: 6000 | BE12: =BD12*BC12 -> 60721.457 | BF12: =+BE12/SUM($F$6:$F$9) -> 0.057713433 | BG12: =VLOOKUP(AW12,Apoio!$L$6:$T$19,9,FALSE)*BE12 -> 12329.322 | BH12: =+BE12*VLOOKUP(AW12,Apoio!$L$6:$U$19,10,FALSE) -> 4705.9129
B13: Soluções Para Caldeiras | C13: =B7&" "&C7 -> Caldeira GPL | I13: * repetir esta tabela para todos os equipamentos | M13: =+Inputs!A10 -> Caldeira | N13: =+IF(M13="Cogeração","",Inputs!B10) -> 150 | O13: =+IF(M13="Cogeração","",Inputs!C10) -> 80 | P13: =+IF(M13="Cogeração","",Inputs!D10) -> GPL | Q13: =+IF(M13="Cogeração","",Inputs!E10) -> 30000 | R13: =+IF(M13="Cogeração","",Inputs!F10) -> m3/ano | S13: =+IF(M13="Cogeração","",Inputs!H10) -> 200 | T13: =+IF(M13="Cogeração","",Inputs!I10) -> 3000 | U13: =+IF(M13="Cogeração","",(101325*(28.96/1000))/(8.314*(S13+273.15))) -> 0.74594414 | V13: =+IF(M13="Cogeração","",T13/3600*U13*$N$5*(S13-$N$6)) -> 51.718794 | W13: =+IF(M13="Cogeração","",V13*0.7) -> 36.203155 | X13: 6000 | Y13: =+IF(M13="Cogeração","",X13*W13) -> 217218.93 | Z13: =+Y13/SUM($F$6:$F$9) -> 0.20645833 | AA13: =+IF(M13="Cogeração","",VLOOKUP(P13,Apoio!L7:T20,9,FALSE)*Y13) -> 49347.285 | AB13: =+Y13*VLOOKUP(P13,Apoio!$L$6:$U$19,10,FALSE) -> 23729.296 | AH13: Equipamento | AI13: Potência | AJ13: Combustível | AK13: Rendimento (%) | AL13: Fator Emissão (kgCO2e/kWh) | AM13: Consumo kWh/ano | AN13: Emissões Kg CO2eq | AO13: Conversão tarifa de energia (€/kWh) | AP13: Custo de energia (€/ano) | AT13: =+Inputs!A27 -> Forno | AU13: =IF(AT13="Cogeração","",Inputs!B10) -> 150 | AV13: =IF(AT13="Cogeração","",Inputs!D27) -> 82.5 | AW13: =IF(AT13="Cogeração","",VLOOKUP(AT13,Inputs!A27:H30,3,FALSE)) -> Gás Natural | AX13: =IF(AT13="Cogeração","",AM15) -> 17647.059 | AY13: =IF(AT13="Cogeração","",Inputs!G27) -> 200 | AZ13: =IF(AT13="Cogeração","",Inputs!H27) -> 3000 | BA13: =IF(AT13="Cogeração","",(101325*(28.96/1000))/(8.314*(AY13+273.15))) -> 0.74594414 | BB13: =IF(AT13="Cogeração","",AZ13/3600*BA13*$N$5*(AY13-$N$6)) -> 51.718794 | BC13: =IF(AT13="Cogeração","",BB13*0.7) -> 36.203155 | BE13: =IF(AT13="Cogeração","",BD13*BC13) -> 0 | BF13: =IF(AT13="Cogeração","",BE13/SUM($F$6:$F$9)) -> 0 | BG13: =IF(AT13="Cogeração","",VLOOKUP(AW13,Apoio!$L$6:$T$19,9,FALSE)*BE13) -> 0 | BH13: =IF(AT13="Cogeração","",BE13*VLOOKUP(AW13,Apoio!$L$6:$U$19,10,FALSE)) -> 0
B14: Alternativas Viáveis | C14: Consumo kWh/ano | D14: Emissões Kg CO2eq | E14: Redução das Emissões (kg CO2eq) | F14: Redução das Emissões (%) | G14: Custo de energia (€) | H14: Poupança económica (€) | M14: =+Inputs!A11 -> Cogeração | N14: =IF(M14="Cogeração","",Inputs!B11) | O14: =IF(M14="Cogeração","",Inputs!C11) | P14: =IF(M14="Cogeração","",Inputs!D11) | Q14: =IF(M14="Cogeração","",Inputs!E11) | R14: =IF(M14="Cogeração","",Inputs!F11) | S14: =IF(M14="Cogeração","",Inputs!H11) | T14: =IF(M14="Cogeração","",Inputs!I11) | U14: =IF(M14="Cogeração","",(101325*(28.96/1000))/(8.314*(S14+273.15))) | V14: =IF(M14="Cogeração","",T14/3600*U14*$N$5*(S14-$N$6)) | W14: =IF(M14="Cogeração","",V14*0.7) | X14: =IF(M14="Cogeração","",6000) | Y14: =IF(M14="Cogeração","",X14*W14) | Z14: =IF(M14="Cogeração","",Y14/SUM($F$6:$F$9)) | AA14: =IF(M14="Cogeração","",VLOOKUP(P14,Apoio!L9:T21,9,FALSE)*Y14) | AB14: =IF(M14="Cogeração","",Y14*VLOOKUP(P14,Apoio!$L$6:$U$19,10,FALSE)) | AH14: =+Inputs!A26 -> Caldeira | AI14: =+Inputs!B26 -> 350 | AJ14: =VLOOKUP(AH14,Inputs!A26:H29,3,FALSE) -> Gás Natural | AK14: =+Inputs!D26 -> 85 | AL14: =VLOOKUP(AJ14,Apoio!L6:T19,9,FALSE) -> 0.2030472 | AM14: =+VLOOKUP(AJ14,$AH$7:$AK$8,4,FALSE)*(AI14/SUMIF($AJ$14:$AJ$17,AJ14,$AI$14:$AI$17)) -> 12352.941 | AN14: =VLOOKUP(AJ14,Apoio!$L$6:$T$19,9,FALSE)*AM14 -> 2508.2301 | AO14: =1/INDEX(Apoio!$P$6:$R$19,MATCH(AJ14,Apoio!$L$6:$L$19,0),MATCH(VLOOKUP(AJ14,Inputs!$A$36:$C$39,3,FALSE),Apoio!$P$5:$R$5,0))*VLOOKUP(AJ14,Inputs!$A$36:$C$39,2,FALSE) -> 0.078 | AP14: =IF(Inputs!$B$34="Sim",AO14*AM14,VLOOKUP(AJ14,Apoio!$L$6:$U$19,10,FALSE)*AM14) -> 963.52941 | AT14: =+Inputs!A28 -> Cogeração | AU14: =+Inputs!B11 -> 200 | AV14: =+Inputs!D28 -> 80 | AW14: =VLOOKUP(AT14,Inputs!A28:H31,3,FALSE) -> Gás Natural | AX14: =+AM16 -> 0 | AY14: =+Inputs!G28 -> 0 | AZ14: =+Inputs!H28 -> 0 | BA14: =+(101325*(28.96/1000))/(8.314*(AY14+273.15)) -> 1.2921233 | BB14: =+AZ14/3600*BA14*$N$5*(AY14-$N$6) -> 0 | BC14: =+BB14*0.7 -> 0 | BD14: 6000 | BE14: =BD14*BC14 -> 0 | BF14: =+BE14/SUM($F$6:$F$9) -> 0 | BG14: =VLOOKUP(AW14,Apoio!$L$6:$T$19,9,FALSE)*BE14 -> 0 | BH14: =+BE14*VLOOKUP(AW14,Apoio!$L$6:$U$19,10,FALSE) -> 0
B15: =IF($E$6/$D$6>Apoio!T6/Apoio!N38,Apoio!M38,"") -> Biometano | C15: =IF(B15="","",IF(B15=$C$7,$F$7,$F$7*($D$7/Apoio!N38))) -> 884329.41 | D15: =IF(B15="","",C15*Apoio!T6) -> 35369.639 | E15: =IF(B15="","",$G$7-D15) -> 178086.47 | F15: =IF(B15="","",(($G$7-D15)/$G$7*100)) -> 83.430018 | G15: =IF(B15="","",C15*Apoio!U6) -> 107888.19 | H15: =IF(B15="","",$I$7-G15) -> -107888.19 | M15: (…) | X15: Total | Y15: =+SUM(Y12:Y14) -> 277940.39 | Z15: =+SUM(Z12:Z14) -> 0.26417176 | AA15: =+SUM(AA12:AA14) -> 61676.606 | AB15: =+SUM(AB12:AB14) -> 28435.209 | AH15: =+Inputs!A27 -> Forno | AI15: =+Inputs!B27 -> 500 | AJ15: =VLOOKUP(AH15,Inputs!A27:H30,3,FALSE) -> Gás Natural | AK15: =+Inputs!D27 -> 82.5 | AL15: =VLOOKUP(AJ15,Apoio!L7:T20,9,FALSE) -> 0.2030472 | AM15: =+VLOOKUP(AJ15,$AH$7:$AK$8,4,FALSE)*(AI15/SUMIF($AJ$14:$AJ$17,AJ15,$AI$14:$AI$17)) -> 17647.059 | AN15: =VLOOKUP(AJ15,Apoio!$L$6:$T$19,9,FALSE)*AM15 -> 3583.1859 | AO15: =1/INDEX(Apoio!$P$6:$R$19,MATCH(AJ15,Apoio!$L$6:$L$19,0),MATCH(VLOOKUP(AJ15,Inputs!$A$36:$C$39,3,FALSE),Apoio!$P$5:$R$5,0))*VLOOKUP(AJ15,Inputs!$A$36:$C$39,2,FALSE) -> 0.078 | AP15: =IF(Inputs!$B$34="Sim",AO15*AM15,VLOOKUP(AJ15,Apoio!$L$6:$U$19,10,FALSE)*AM15) -> 1376.4706 | AT15: =+Inputs!A29 -> Queimador (Dedicado a estufas ou banhos térmicos) | AU15: =+Inputs!B12 -> 60 | AV15: =+Inputs!D29 -> 80 | AW15: =VLOOKUP(AT15,Inputs!A29:H32,3,FALSE) -> Gás Natural | AX15: =+AM17 -> 0 | AY15: 122 | AZ15: =+Inputs!H29 -> 0 | BA15: =+(101325*(28.96/1000))/(8.314*(AY15+273.15)) -> 0.89318858 | BB15: =+AZ15/3600*BA15*$N$5*(AY15-$N$6) -> 0 | BC15: =+BB15*0.7 -> 0 | BD15: 6000 | BE15: =BD15*BC15 -> 0 | BF15: =+BE15/SUM($F$6:$F$9) -> 0 | BG15: =VLOOKUP(AW15,Apoio!$L$6:$T$19,9,FALSE)*BE15 -> 0 | BH15: =+BE15*VLOOKUP(AW15,Apoio!$L$6:$U$19,10,FALSE) -> 0
B16: =IF($E$6/$D$6>Apoio!T7/Apoio!N39,Apoio!M39,"") -> Hidrogénio | C16: =IF(B16="","",IF(B16=$C$7,$F$7,$F$7*($D$7/Apoio!N39))) -> 884329.41 | D16: =IF(B16="","",C16*Apoio!T7) -> 0 | E16: =IF(B16="","",$G$7-D16) -> 213456.11 | F16: =IF(B16="","",(($G$7-D16)/$G$7*100)) -> 100 | G16: =IF(B16="","",C16*Apoio!U7) -> 172444.24 | H16: =IF(B16="","",$I$7-G16) -> -172444.24 | AH16: =+Inputs!A28 -> Cogeração | AI16: =+Inputs!B28 -> 0 | AJ16: =VLOOKUP(AH16,Inputs!A28:H31,3,FALSE) -> Gás Natural | AK16: =+Inputs!D28 -> 80 | AL16: =VLOOKUP(AJ16,Apoio!L9:T21,9,FALSE) -> 0.2030472 | AM16: =+VLOOKUP(AJ16,$AH$7:$AK$8,4,FALSE)*(AI16/SUMIF($AJ$14:$AJ$17,AJ16,$AI$14:$AI$17)) -> 0 | AN16: =VLOOKUP(AJ16,Apoio!$L$6:$T$19,9,FALSE)*AM16 -> 0 | AO16: =1/INDEX(Apoio!$P$6:$R$19,MATCH(AJ16,Apoio!$L$6:$L$19,0),MATCH(VLOOKUP(AJ16,Inputs!$A$36:$C$39,3,FALSE),Apoio!$P$5:$R$5,0))*VLOOKUP(AJ16,Inputs!$A$36:$C$39,2,FALSE) -> 0.078 | AP16: =IF(Inputs!$B$34="Sim",AO16*AM16,VLOOKUP(AJ16,Apoio!$L$6:$U$19,10,FALSE)*AM16) -> 0 | BD16: Total | BE16: =+SUM(BE12:BE15) -> 60721.457 | BF16: =+SUM(BF12:BF15) -> 0.057713433 | BG16: =+SUM(BG12:BG14) -> 12329.322 | BH16: =+SUM(BH12:BH15) -> 4705.9129
B17: =IF($E$6/$D$6>Apoio!T8/Apoio!N40,Apoio!M40,"") -> Biomassa | C17: =IF(B17="","",IF(B17=$C$7,$F$7,$F$7*($D$7/Apoio!N40))) -> 884329.41 | D17: =IF(B17="","",C17*Apoio!T8) -> 0 | E17: =IF(B17="","",$G$7-D17) -> 213456.11 | F17: =IF(B17="","",(($G$7-D17)/$G$7*100)) -> 100 | G17: =IF(B17="","",C17*Apoio!U8) -> 9096.2123 | H17: =IF(B17="","",$I$7-G17) -> -9096.2123 | AH17: =+Inputs!A29 -> Queimador (Dedicado a estufas ou banhos térmicos) | AI17: =+Inputs!B29 -> 0 | AJ17: =VLOOKUP(AH17,Inputs!A29:H32,3,FALSE) -> Gás Natural | AK17: =+Inputs!D29 -> 80 | AL17: =VLOOKUP(AJ17,Apoio!L11:T22,9,FALSE) -> 0.2030472 | AM17: =+VLOOKUP(AJ17,$AH$7:$AK$8,4,FALSE)*(AI17/SUMIF($AJ$14:$AJ$17,AJ17,$AI$14:$AI$17)) -> 0 | AN17: =VLOOKUP(AJ17,Apoio!$L$6:$T$19,9,FALSE)*AM17 -> 0 | AO17: =1/INDEX(Apoio!$P$6:$R$19,MATCH(AJ17,Apoio!$L$6:$L$19,0),MATCH(VLOOKUP(AJ17,Inputs!$A$36:$C$39,3,FALSE),Apoio!$P$5:$R$5,0))*VLOOKUP(AJ17,Inputs!$A$36:$C$39,2,FALSE) -> 0.078 | AP17: =IF(Inputs!$B$34="Sim",AO17*AM17,VLOOKUP(AJ17,Apoio!$L$6:$U$19,10,FALSE)*AM17) -> 0
B18: =IF($E$6/$D$6>Apoio!T9/Apoio!N41,Apoio!M41,"") -> GN + Biometano 50 % | C18: =IF(B18="","",IF(B18=$C$7,$F$7,$F$7*($D$7/Apoio!N41))) -> 884329.41 | D18: =IF(B18="","",C18*Apoio!T9) -> 97035.698 | E18: =IF(B18="","",$G$7-D18) -> 116420.41 | F18: =IF(B18="","",(($G$7-D18)/$G$7*100)) -> 54.540679 | G18: =IF(B18="","",C18*Apoio!U9) -> 88211.859 | H18: =IF(B18="","",$I$7-G18) -> -88211.859 | AH18: (…)
B19: =IF($E$6/$D$6>Apoio!T10/Apoio!N42,Apoio!M42,"") -> Eletricidade | C19: =IF(B19="","",IF(B19=$C$7,$F$7,$F$7*($D$7/Apoio!N42))) -> 774927.84 | D19: =IF(B19="","",C19*Apoio!T10) -> 117014.1 | E19: =IF(B19="","",$G$7-D19) -> 96442.007 | F19: =IF(B19="","",(($G$7-D19)/$G$7*100)) -> 45.181188 | G19: =IF(B19="","",C19*Apoio!U10) -> 97299.939 | H19: =IF(B19="","",$I$7-G19) -> -97299.939 | AH19: Cenários para cada equipamento
B20: =IF($E$6/$D$6>Apoio!T11/Apoio!N43,Apoio!M43,"") -> GN + H2 20 % | C20: =IF(B20="","",IF(B20=$C$7,$F$7,$F$7*($D$7/Apoio!N43))) -> 884329.41 | D20: =IF(B20="","",C20*Apoio!T11) -> 166406.03 | E20: =IF(B20="","",$G$7-D20) -> 47050.076 | F20: =IF(B20="","",(($G$7-D20)/$G$7*100)) -> 22.042038 | G20: =IF(B20="","",C20*Apoio!U11) -> 89317.271 | H20: =IF(B20="","",$I$7-G20) -> -89317.271
B21: =IF($E$6/$D$6>Apoio!T12/Apoio!N44,Apoio!M44,"") -> GN + H2 10 % | C21: =IF(B21="","",IF(B21=$C$7,$F$7,$F$7*($D$7/Apoio!N44))) -> 884329.41 | D21: =IF(B21="","",C21*Apoio!T12) -> 173559.55 | E21: =IF(B21="","",$G$7-D21) -> 39896.559 | F21: =IF(B21="","",(($G$7-D21)/$G$7*100)) -> 18.690755 | G21: =IF(B21="","",C21*Apoio!U12) -> 78926.4 | H21: =IF(B21="","",$I$7-G21) -> -78926.4 | AH21: Soluções Para Caldeiras | AI21: =AH16&" "&AJ16 -> Cogeração Gás Natural | AO21: * repetir esta tabela para todos os equipamentos
B22: =IF($E$6/$D$6>Apoio!T13/Apoio!N45,Apoio!M45,"") -> Gás Natural | C22: =IF(B22="","",IF(B22=$C$7,$F$7,$F$7*($D$7/Apoio!N45))) -> 884329.41 | D22: =IF(B22="","",C22*Apoio!T13) -> 179560.61 | E22: =IF(B22="","",$G$7-D22) -> 33895.5 | F22: =IF(B22="","",(($G$7-D22)/$G$7*100)) -> 15.879377 | G22: =IF(B22="","",C22*Apoio!U13) -> 68535.529 | H22: =IF(B22="","",$I$7-G22) -> -68535.529 | AH22: Alternativas Viáveis | AI22: Consumo kWh/ano | AJ22: Emissões Kg CO2eq | AK22: Redução das Emissões (kg CO2eq) | AL22: Redução das Emissões (%) | AM22: Custo de energia (€) | AN22: Poupança económica (€)
B23: =IF($E$6/$D$6>Apoio!T14/Apoio!N46,Apoio!M46,"") | C23: =IF(B23="","",IF(B23=$C$7,$F$7,$F$7*($D$7/Apoio!N46))) | D23: =IF(B23="","",C23*Apoio!T14) | E23: =IF(B23="","",$G$7-D23) | F23: =IF(B23="","",(($G$7-D23)/$G$7*100)) | G23: =IF(B23="","",C23*Apoio!U14) | H23: =IF(B23="","",$I$7-G23) | AH23: =IF($AL$16/$AK$16>Apoio!T6/Apoio!N38,Apoio!M38,"") -> Biometano | AI23: =IF(AH23="","",IF(AH23=$AJ$16,$AM$16,$AM$16*($AK$16/Apoio!N38))) -> 0 | AJ23: =IF(AH23="","",AI23*Apoio!T6) -> 0 | AK23: =IF(AH23="","",$AN$16-AJ23) -> 0 | AL23: =IF(AH23="","",(($AN$16-AJ23)/$AN$16*100)) -> #DIV/0! | AM23: =IF(AH23="","",AI23*Apoio!U6) -> 0 | AN23: =IF(AH23="","",$AP$16-AM23) -> 0
B24: =IF($E$6/$D$6>Apoio!T15/Apoio!N47,Apoio!M47,"") | C24: =IF(B24="","",IF(B24=$C$7,$F$7,$F$7*($D$7/Apoio!N47))) | D24: =IF(B24="","",C24*Apoio!T15) | E24: =IF(B24="","",$G$7-D24) | F24: =IF(B24="","",(($G$7-D24)/$G$7*100)) | G24: =IF(B24="","",C24*Apoio!U15) | H24: =IF(B24="","",$I$7-G24) | AH24: =IF($AL$16/$AK$16>Apoio!T7/Apoio!N39,Apoio!M39,"") -> Hidrogénio | AI24: =IF(AH24="","",IF(AH24=$AJ$16,$AM$16,$AM$16*($AK$16/Apoio!N39))) -> 0 | AJ24: =IF(AH24="","",AI24*Apoio!T7) -> 0 | AK24: =IF(AH24="","",$AN$16-AJ24) -> 0 | AL24: =IF(AH24="","",(($AN$16-AJ24)/$AN$16*100)) -> #DIV/0! | AM24: =IF(AH24="","",AI24*Apoio!U7) -> 0 | AN24: =IF(AH24="","",$AP$16-AM24) -> 0
B25: =IF($E$6/$D$6>Apoio!T16/Apoio!N48,Apoio!M48,"") | C25: =IF(B25="","",IF(B25=$C$7,$F$7,$F$7*($D$7/Apoio!N48))) | D25: =IF(B25="","",C25*Apoio!T16) | E25: =IF(B25="","",$G$7-D25) | F25: =IF(B25="","",(($G$7-D25)/$G$7*100)) | G25: =IF(B25="","",C25*Apoio!U16) | H25: =IF(B25="","",$I$7-G25) | AH25: =IF($AL$16/$AK$16>Apoio!T8/Apoio!N40,Apoio!M40,"") -> Biomassa | AI25: =IF(AH25="","",IF(AH25=$AJ$16,$AM$16,$AM$16*($AK$16/Apoio!N40))) -> 0 | AJ25: =IF(AH25="","",AI25*Apoio!T9) -> 0 | AK25: =IF(AH25="","",$AN$16-AJ25) -> 0 | AL25: =IF(AH25="","",(($AN$16-AJ25)/$AN$16*100)) -> #DIV/0! | AM25: =IF(AH25="","",AI25*Apoio!U8) -> 0 | AN25: =IF(AH25="","",$AP$16-AM25) -> 0
B26: =IF($E$6/$D$6>Apoio!T17/Apoio!N49,Apoio!M49,"") | C26: =IF(B26="","",IF(B26=$C$7,$F$7,$F$7*($D$7/Apoio!N49))) | D26: =IF(B26="","",C26*Apoio!T17) | E26: =IF(B26="","",$G$7-D26) | F26: =IF(B26="","",(($G$7-D26)/$G$7*100)) | G26: =IF(B26="","",C26*Apoio!U17) | H26: =IF(B26="","",$I$7-G26) | AH26: =IF($AL$16/$AK$16>Apoio!T9/Apoio!N41,Apoio!M41,"") -> GN + Biometano 50 % | AI26: =IF(AH26="","",IF(AH26=$AJ$16,$AM$16,$AM$16*($AK$16/Apoio!N41))) -> 0 | AJ26: =IF(AH26="","",AI26*Apoio!T8) -> 0 | AK26: =IF(AH26="","",$AN$16-AJ26) -> 0 | AL26: =IF(AH26="","",(($AN$16-AJ26)/$AN$16*100)) -> #DIV/0! | AM26: =IF(AH26="","",AI26*Apoio!U9) -> 0 | AN26: =IF(AH26="","",$AP$16-AM26) -> 0
B27: =IF($E$6/$D$6>Apoio!T18/Apoio!N50,Apoio!M50,"") | C27: =IF(B27="","",IF(B27=$C$7,$F$7,$F$7*($D$7/Apoio!N50))) | D27: =IF(B27="","",C27*Apoio!T18) | E27: =IF(B27="","",$G$7-D27) | F27: =IF(B27="","",(($G$7-D27)/$G$7*100)) | G27: =IF(B27="","",C27*Apoio!U18) | H27: =IF(B27="","",$I$7-G27) | AH27: =IF($AL$16/$AK$16>Apoio!T10/Apoio!N42,Apoio!M42,"") -> Eletricidade | AI27: =IF(AH27="","",IF(AH27=$AJ$16,$AM$16,$AM$16*($AK$16/Apoio!N42))) -> 0 | AJ27: =IF(AH27="","",AI27*Apoio!T11) -> 0 | AK27: =IF(AH27="","",$AN$16-AJ27) -> 0 | AL27: =IF(AH27="","",(($AN$16-AJ27)/$AN$16*100)) -> #DIV/0! | AM27: =IF(AH27="","",AI27*Apoio!U10) -> 0 | AN27: =IF(AH27="","",$AP$16-AM27) -> 0
AH28: =IF($AL$16/$AK$16>Apoio!T11/Apoio!N43,Apoio!M43,"") -> GN + H2 20 % | AI28: =IF(AH28="","",IF(AH28=$AJ$16,$AM$16,$AM$16*($AK$16/Apoio!N43))) -> 0 | AJ28: =IF(AH28="","",AI28*Apoio!T12) -> 0 | AK28: =IF(AH28="","",$AN$16-AJ28) -> 0 | AL28: =IF(AH28="","",(($AN$16-AJ28)/$AN$16*100)) -> #DIV/0! | AM28: =IF(AH28="","",AI28*Apoio!U11) -> 0 | AN28: =IF(AH28="","",$AP$16-AM28) -> 0
AH29: =IF($AL$16/$AK$16>Apoio!T12/Apoio!N44,Apoio!M44,"") -> GN + H2 10 % | AI29: =IF(AH29="","",IF(AH29=$AJ$16,$AM$16,$AM$16*($AK$16/Apoio!N44))) -> 0 | AJ29: =IF(AH29="","",AI29*Apoio!T10) -> 0 | AK29: =IF(AH29="","",$AN$16-AJ29) -> 0 | AL29: =IF(AH29="","",(($AN$16-AJ29)/$AN$16*100)) -> #DIV/0! | AM29: =IF(AH29="","",AI29*Apoio!U12) -> 0 | AN29: =IF(AH29="","",$AP$16-AM29) -> 0
B30: Soluções Para Cogeração | C30: =B8&" "&C8 -> Cogeração Gás Natural | AH30: =IF($AL$16/$AK$16>Apoio!T13/Apoio!N45,Apoio!M45,"") -> Gás Natural | AI30: =IF(AH30="","",IF(AH30=$AJ$16,$AM$16,$AM$16*($AK$16/Apoio!N45))) -> 0 | AJ30: =IF(AH30="","",AI30*Apoio!T13) -> 0 | AK30: =IF(AH30="","",$AN$16-AJ30) -> 0 | AL30: =IF(AH30="","",(($AN$16-AJ30)/$AN$16*100)) -> #DIV/0! | AM30: =IF(AH30="","",AI30*Apoio!U13) -> 0 | AN30: =IF(AH30="","",$AP$16-AM30) -> 0
B31: Alternativas Viáveis | C31: Consumo kWh/ano | D31: Emissões Kg CO2eq | E31: Redução das Emissões (kg CO2eq) | F31: Redução das Emissões (%) | G31: Custo de energia (€) | H31: Poupança económica (€) | AH31: =IF($AL$16/$AK$16>Apoio!T14/Apoio!N46,Apoio!M46,"") | AI31: =IF(AH31="","",IF(AH31=$AJ$16,$AM$16,$AM$16*($AK$16/Apoio!N46))) | AJ31: =IF(AH31="","",AI31*Apoio!T14) | AK31: =IF(AH31="","",$AN$16-AJ31) | AL31: =IF(AH31="","",(($AN$16-AJ31)/$AN$16*100)) | AM31: =IF(AH31="","",AI31*Apoio!U14) | AN31: =IF(AH31="","",$AP$16-AM31)
B32: =IF($E$8/$D$8>Apoio!T6/Apoio!N54,Apoio!M54,"") -> Biometano | C32: =IF(B32="","",IF(B32=$C$8,$F$8,$F$8*($D$8/Apoio!N54))) -> 54857.143 | D32: =IF(B32="","",C32*Apoio!T6) -> 2194.0663 | E32: =IF(B32="","",$G$8-D32) -> 9988.7657 | F32: =IF(B32="","",(($G$8-D32)/$G$8*100)) -> 81.990507 | G32: =IF(B32="","",C32*Apoio!U6) -> 6692.5714 | H32: =IF(B32="","",$I$8-G32) -> -2012.5714 | AH32: =IF($AL$16/$AK$16>Apoio!T15/Apoio!N47,Apoio!M47,"") | AI32: =IF(AH32="","",IF(AH32=$AJ$16,$AM$16,$AM$16*($AK$16/Apoio!N47))) | AJ32: =IF(AH32="","",AI32*Apoio!T15) | AK32: =IF(AH32="","",$AN$16-AJ32) | AL32: =IF(AH32="","",(($AN$16-AJ32)/$AN$16*100)) | AM32: =IF(AH32="","",AI32*Apoio!U15) | AN32: =IF(AH32="","",$AP$16-AM32)
B33: =IF($E$8/$D$8>Apoio!T7/Apoio!N55,Apoio!M55,"") -> Hidrogénio | C33: =IF(B33="","",IF(B33=$C$8,$F$8,$F$8*($D$8/Apoio!N55))) -> 54857.143 | D33: =IF(B33="","",C33*Apoio!T7) -> 0 | E33: =IF(B33="","",$G$8-D33) -> 12182.832 | F33: =IF(B33="","",(($G$8-D33)/$G$8*100)) -> 100 | G33: =IF(B33="","",C33*Apoio!U7) -> 10697.143 | H33: =IF(B33="","",$I$8-G33) -> -6017.1429 | AH33: =IF($AL$16/$AK$16>Apoio!T16/Apoio!N48,Apoio!M48,"") | AI33: =IF(AH33="","",IF(AH33=$AJ$16,$AM$16,$AM$16*($AK$16/Apoio!N48))) | AJ33: =IF(AH33="","",AI33*Apoio!T16) | AK33: =IF(AH33="","",$AN$16-AJ33) | AL33: =IF(AH33="","",(($AN$16-AJ33)/$AN$16*100)) | AM33: =IF(AH33="","",AI33*Apoio!U16) | AN33: =IF(AH33="","",$AP$16-AM33)
B34: =IF($E$8/$D$8>Apoio!T8/Apoio!N56,Apoio!M56,"") -> Biomassa | C34: =IF(B34="","",IF(B34=$C$8,$F$8,$F$8*($D$8/Apoio!N56))) -> 54857.143 | D34: =IF(B34="","",C34*Apoio!T8) -> 0 | E34: =IF(B34="","",$G$8-D34) -> 12182.832 | F34: =IF(B34="","",(($G$8-D34)/$G$8*100)) -> 100 | G34: =IF(B34="","",C34*Apoio!U8) -> 564.26057 | H34: =IF(B34="","",$I$8-G34) -> 4115.7394 | AH34: =IF($AL$16/$AK$16>Apoio!T17/Apoio!N49,Apoio!M49,"") | AI34: =IF(AH34="","",IF(AH34=$AJ$16,$AM$16,$AM$16*($AK$16/Apoio!N49))) | AJ34: =IF(AH34="","",AI34*Apoio!T17) | AK34: =IF(AH34="","",$AN$16-AJ34) | AL34: =IF(AH34="","",(($AN$16-AJ34)/$AN$16*100)) | AM34: =IF(AH34="","",AI34*Apoio!U17) | AN34: =IF(AH34="","",$AP$16-AM34)
B35: =IF($E$8/$D$8>Apoio!T9/Apoio!N57,Apoio!M57,"") -> GN + Biometano 50 % | C35: =IF(B35="","",IF(B35=$C$8,$F$8,$F$8*($D$8/Apoio!N57))) -> 54857.143 | D35: =IF(B35="","",C35*Apoio!T9) -> 6019.3646 | E35: =IF(B35="","",$G$8-D35) -> 6163.4674 | F35: =IF(B35="","",(($G$8-D35)/$G$8*100)) -> 50.591418 | G35: =IF(B35="","",C35*Apoio!U9) -> 5472 | H35: =IF(B35="","",$I$8-G35) -> -792 | AH35: =IF($AL$16/$AK$16>Apoio!T18/Apoio!N50,Apoio!M50,"") | AI35: =IF(AH35="","",IF(AH35=$AJ$16,$AM$16,$AM$16*($AK$16/Apoio!N50))) | AJ35: =IF(AH35="","",AI35*Apoio!T18) | AK35: =IF(AH35="","",$AN$16-AJ35) | AL35: =IF(AH35="","",(($AN$16-AJ35)/$AN$16*100)) | AM35: =IF(AH35="","",AI35*Apoio!U18) | AN35: =IF(AH35="","",$AP$16-AM35)
B36: =IF($E$8/$D$8>Apoio!T11/Apoio!N58,Apoio!M58,"") -> GN + H2 20 % | C36: =IF(B36="","",IF(B36=$C$8,$F$8,$F$8*($D$8/Apoio!N58))) -> 54857.143 | D36: =IF(B36="","",C36*Apoio!T11) -> 10322.578 | E36: =IF(B36="","",$G$8-D36) -> 1860.2537 | F36: =IF(B36="","",(($G$8-D36)/$G$8*100)) -> 15.269469 | G36: =IF(B36="","",C36*Apoio!U11) -> 5540.5714 | H36: =IF(B36="","",$I$8-G36) -> -860.57143
B37: =IF($E$8/$D$8>Apoio!T12/Apoio!N59,Apoio!M59,"") -> GN + H2 10 % | C37: =IF(B37="","",IF(B37=$C$8,$F$8,$F$8*($D$8/Apoio!N59))) -> 54857.143 | D37: =IF(B37="","",C37*Apoio!T12) -> 10766.329 | E37: =IF(B37="","",$G$8-D37) -> 1416.5033 | F37: =IF(B37="","",(($G$8-D37)/$G$8*100)) -> 11.627045 | G37: =IF(B37="","",C37*Apoio!U12) -> 4896 | H37: =IF(B37="","",$I$8-G37) -> -216 | AH37: Soluções Para Cogeração | AI37: =AH15&" "&AJ15 -> Forno Gás Natural
B38: =IF($E$8/$D$8>Apoio!T13/Apoio!N60,Apoio!M60,"") -> Gás Natural | C38: =IF(B38="","",IF(B38=$C$8,$F$8,$F$8*($D$8/Apoio!N60))) -> 60000 | D38: =IF(B38="","",C38*Apoio!T13) -> 12182.832 | E38: =IF(B38="","",$G$8-D38) -> 0 | F38: =IF(B38="","",(($G$8-D38)/$G$8*100)) -> 0 | G38: =IF(B38="","",C38*Apoio!U13) -> 4650 | H38: =IF(B38="","",$I$8-G38) -> 30 | AH38: Alternativas Viáveis | AI38: Consumo kWh/ano | AJ38: Emissões Kg CO2eq | AK38: Redução das Emissões (kg CO2eq) | AL38: Redução das Emissões (%) | AM38: Custo de energia (€) | AN38: Poupança económica (€)
B39: =IF($E$8/$D$8>Apoio!T14/Apoio!N61,Apoio!M61,"") | C39: =IF(B39="","",IF(B39=$C$8,$F$8,$F$8*($D$8/Apoio!N61))) | D39: =IF(B39="","",C39*Apoio!T14) | E39: =IF(B39="","",$G$8-D39) | F39: =IF(B39="","",(($G$8-D39)/$G$8*100)) | G39: =IF(B39="","",C39*Apoio!U14) | H39: =IF(B39="","",$I$8-G39) | AH39: =IF($AL$15/$AK$15>Apoio!T6/Apoio!N54,Apoio!M54,"") -> Biometano | AI39: =IF(AH39="","",IF(AH39=$AJ$15,$AM$15,$AM$15*($AK$15/Apoio!N54))) -> 16638.655 | AJ39: =IF(AH39="","",AI39*Apoio!T6) -> 665.47966 | AK39: =IF(AH39="","",$AN$15-AJ39) -> 2917.7062 | AL39: =IF(AH39="","",(($AN$15-AJ39)/$AN$15*100)) -> 81.42771 | AM39: =IF(AH39="","",AI39*Apoio!U6) -> 2029.916 | AN39: =IF(AH39="","",$AP$15-AM39) -> -653.44538
B40: =IF($E$8/$D$8>Apoio!T15/Apoio!N62,Apoio!M62,"") | C40: =IF(B40="","",IF(B40=$C$8,$F$8,$F$8*($D$8/Apoio!N62))) | D40: =IF(B40="","",C40*Apoio!T15) | E40: =IF(B40="","",$G$8-D40) | F40: =IF(B40="","",(($G$8-D40)/$G$8*100)) | G40: =IF(B40="","",C40*Apoio!U15) | H40: =IF(B40="","",$I$8-G40) | AH40: =IF($AL$15/$AK$15>Apoio!T7/Apoio!N55,Apoio!M55,"") -> Hidrogénio | AI40: =IF(AH40="","",IF(AH40=$AJ$15,$AM$15,$AM$15*($AK$15/Apoio!N55))) -> 16638.655 | AJ40: =IF(AH40="","",AI40*Apoio!T7) -> 0 | AK40: =IF(AH40="","",$AN$15-AJ40) -> 3583.1859 | AL40: =IF(AH40="","",(($AN$15-AJ40)/$AN$15*100)) -> 100 | AM40: =IF(AH40="","",AI40*Apoio!U7) -> 3244.5378 | AN40: =IF(AH40="","",$AP$15-AM40) -> -1868.0672
B41: =IF($E$8/$D$8>Apoio!T16/Apoio!N63,Apoio!M63,"") | C41: =IF(B41="","",IF(B41=$C$8,$F$8,$F$8*($D$8/Apoio!N63))) | D41: =IF(B41="","",C41*Apoio!T16) | E41: =IF(B41="","",$G$8-D41) | F41: =IF(B41="","",(($G$8-D41)/$G$8*100)) | G41: =IF(B41="","",C41*Apoio!U16) | H41: =IF(B41="","",$I$8-G41) | AH41: =IF($AL$15/$AK$15>Apoio!T9/Apoio!N56,Apoio!M56,"") -> Biomassa | AI41: =IF(AH41="","",IF(AH41=$AJ$15,$AM$15,$AM$15*($AK$15/Apoio!N56))) -> 16638.655 | AJ41: =IF(AH41="","",AI41*Apoio!T9) -> 1825.7264 | AK41: =IF(AH41="","",$AN$15-AJ41) -> 1757.4595 | AL41: =IF(AH41="","",(($AN$15-AJ41)/$AN$15*100)) -> 49.0474 | AM41: =IF(AH41="","",AI41*Apoio!U9) -> 1659.7059 | AN41: =IF(AH41="","",$AP$15-AM41) -> -283.23529
B42: =IF($E$8/$D$8>Apoio!T17/Apoio!N64,Apoio!M64,"") | C42: =IF(B42="","",IF(B42=$C$8,$F$8,$F$8*($D$8/Apoio!N64))) | D42: =IF(B42="","",C42*Apoio!T17) | E42: =IF(B42="","",$G$8-D42) | F42: =IF(B42="","",(($G$8-D42)/$G$8*100)) | G42: =IF(B42="","",C42*Apoio!U17) | H42: =IF(B42="","",$I$8-G42) | AH42: =IF($AL$15/$AK$15>Apoio!T8/Apoio!N57,Apoio!M57,"") -> GN + Biometano 50 % | AI42: =IF(AH42="","",IF(AH42=$AJ$15,$AM$15,$AM$15*($AK$15/Apoio!N57))) -> 16638.655 | AJ42: =IF(AH42="","",AI42*Apoio!T8) -> 0 | AK42: =IF(AH42="","",$AN$15-AJ42) -> 3583.1859 | AL42: =IF(AH42="","",(($AN$15-AJ42)/$AN$15*100)) -> 100 | AM42: =IF(AH42="","",AI42*Apoio!U8) -> 171.14521 | AN42: =IF(AH42="","",$AP$15-AM42) -> 1205.3254
...

Sheet Outputs
B2: Resultados (Consumo por equipamento) | X2: Resultados (Consumo por fábrica)
B4: Mudança de vetor energético | X4: Mudança de vetor energético
C5: Cenário | D5: Emissões [ton Co2/ano] | E5: Descarbonização [%] | Y5: Cenário | Z5: Emissões [ton Co2/ano] | AA5: Descarbonização [%]
C6: Base | D6: =+SUM(Processamento!G6:G8)/1000 -> 236.29892 | E6: - | Y6: Base | Z6: =+SUM(Processamento!AN14:AN17)/1000 -> 6.091416 | AA6: -
C7: =+Processamento!B15 -> Biometano | D7: =+IF(C7="","",(SUMIF(Processamento!$B$15:$B$102,Outputs!C7,Processamento!$D$15:$D$102))/1000) -> 39.600618 | E7: =+IF(C7="","",($D$6-D7)/$D$6) -> 0.83241304 | Y7: =+Processamento!AH23 -> Biometano | Z7: =IF(Y7="","",SUMIF(Processamento!$AH$23:$AH$111,Y7,Processamento!$AJ$23:$AJ$111)/1000) -> 1.1745197 | AA7: =+IF(Y7="","",($Z$6-Z7)/$Z$6) -> 0.80718446
C8: =+Processamento!B16 -> Hidrogénio | D8: =+IF(C8="","",(SUMIF(Processamento!$B$15:$B$102,Outputs!C8,Processamento!$D$15:$D$102))/1000) -> 0 | E8: =+IF(C8="","",($D$6-D8)/$D$6) -> 1 | Y8: =+Processamento!AH24 -> Hidrogénio | Z8: =IF(Y8="","",SUMIF(Processamento!$AH$23:$AH$111,Y8,Processamento!$AJ$23:$AJ$111)/1000) -> 0 | AA8: =+IF(Y8="","",($Z$6-Z8)/$Z$6) -> 1
C9: =+Processamento!B17 -> Biomassa | D9: =+IF(C9="","",(SUMIF(Processamento!$B$15:$B$102,Outputs!C9,Processamento!$D$15:$D$102))/1000) -> 0.0020654682 | E9: =+IF(C9="","",($D$6-D9)/$D$6) -> 0.99999126 | Y9: =+Processamento!AH25 -> Biomassa | Z9: =IF(Y9="","",SUMIF(Processamento!$AH$23:$AH$111,Y9,Processamento!$AJ$23:$AJ$111)/1000) -> 3.2222646 | AA9: =+IF(Y9="","",($Z$6-Z9)/$Z$6) -> 0.47101551
C10: =+Processamento!B18 -> GN + Biometano 50 % | D10: =+IF(C10="","",(SUMIF(Processamento!$B$15:$B$102,Outputs!C10,Processamento!$D$15:$D$102))/1000) -> 108.64121 | E10: =+IF(C10="","",($D$6-D10)/$D$6) -> 0.54023821 | Y10: =+Processamento!AH26 -> GN + Biometano 50 % | Z10: =IF(Y10="","",SUMIF(Processamento!$AH$23:$AH$111,Y10,Processamento!$AJ$23:$AJ$111)/1000) -> 0 | AA10: =+IF(Y10="","",($Z$6-Z10)/$Z$6) -> 1
C11: =+Processamento!B19 -> Eletricidade | D11: =+IF(C11="","",(SUMIF(Processamento!$B$15:$B$102,Outputs!C11,Processamento!$D$15:$D$102))/1000) -> 124.10368 | E11: =+IF(C11="","",($D$6-D11)/$D$6) -> 0.47480218 | Y11: =+Processamento!AH27 -> Eletricidade | Z11: =IF(Y11="","",SUMIF(Processamento!$AH$23:$AH$111,Y11,Processamento!$AJ$23:$AJ$111)/1000) -> 2.2076045 | AA11: =+IF(Y11="","",($Z$6-Z11)/$Z$6) -> 0.63758764
C12: =+Processamento!B20 -> GN + H2 20 % | D12: =+IF(C12="","",(SUMIF(Processamento!$B$15:$B$102,Outputs!C12,Processamento!$D$15:$D$102))/1000) -> 186.31197 | E12: =+IF(C12="","",($D$6-D12)/$D$6) -> 0.21154116 | N12: Gráfico referente ao caso do biometano | Y12: =+Processamento!AH28 -> GN + H2 20 % | Z12: =IF(Y12="","",SUMIF(Processamento!$AH$23:$AH$111,Y12,Processamento!$AJ$23:$AJ$111)/1000) -> 5.7633923 | AA12: =+IF(Y12="","",($Z$6-Z12)/$Z$6) -> 0.053850155 | AK12: Gráfico referente ao caso do biometano
C13: =+Processamento!B21 -> GN + H2 10 % | D13: =+IF(C13="","",(SUMIF(Processamento!$B$15:$B$102,Outputs!C13,Processamento!$D$15:$D$102))/1000) -> 194.3202 | E13: =+IF(C13="","",($D$6-D13)/$D$6) -> 0.17765091 | Y13: =+Processamento!AH29 -> GN + H2 10 % | Z13: =IF(Y13="","",SUMIF(Processamento!$AH$23:$AH$111,Y13,Processamento!$AJ$23:$AJ$111)/1000) -> 4.4342552 | AA13: =+IF(Y13="","",($Z$6-Z13)/$Z$6) -> 0.27204854
C14: =+Processamento!B22 -> Gás Natural | D14: =+IF(C14="","",(SUMIF(Processamento!$B$15:$B$102,Outputs!C14,Processamento!$D$15:$D$102))/1000) -> 202.40748 | E14: =+IF(C14="","",($D$6-D14)/$D$6) -> 0.14342613 | Y14: =+Processamento!AH30 -> Gás Natural | Z14: =IF(Y14="","",SUMIF(Processamento!$AH$23:$AH$111,Y14,Processamento!$AJ$23:$AJ$111)/1000) -> 3.5831859 | AA14: =+IF(Y14="","",($Z$6-Z14)/$Z$6) -> 0.41176471
C15: =+Processamento!B23 | D15: =+IF(C15="","",(SUMIF(Processamento!$B$15:$B$102,Outputs!C15,Processamento!$D$15:$D$102))/1000) | E15: =+IF(C15="","",($D$6-D15)/$D$6) | Y15: =+Processamento!AH31 | Z15: =IF(Y15="","",SUMIF(Processamento!$AH$23:$AH$111,Y15,Processamento!$AJ$23:$AJ$111)/1000) | AA15: =+IF(Y15="","",($Z$6-Z15)/$Z$6)
C16: =+Processamento!B24 | D16: =+IF(C16="","",(SUMIF(Processamento!$B$15:$B$102,Outputs!C16,Processamento!$D$15:$D$102))/1000) | E16: =+IF(C16="","",($D$6-D16)/$D$6) | Y16: =+Processamento!AH32 | Z16: =IF(Y16="","",SUMIF(Processamento!$AH$23:$AH$111,Y16,Processamento!$AJ$23:$AJ$111)/1000) | AA16: =+IF(Y16="","",($Z$6-Z16)/$Z$6)
C17: =+Processamento!B25 | D17: =+IF(C17="","",(SUMIF(Processamento!$B$15:$B$102,Outputs!C17,Processamento!$D$15:$D$102))/1000) | E17: =+IF(C17="","",($D$6-D17)/$D$6) | Y17: =+Processamento!AH33 | Z17: =IF(Y17="","",SUMIF(Processamento!$AH$23:$AH$111,Y17,Processamento!$AJ$23:$AJ$111)/1000) | AA17: =+IF(Y17="","",($Z$6-Z17)/$Z$6)
C18: =+Processamento!B26 | D18: =+IF(C18="","",(SUMIF(Processamento!$B$15:$B$102,Outputs!C18,Processamento!$D$15:$D$102))/1000) | E18: =+IF(C18="","",($D$6-D18)/$D$6) | Y18: =+Processamento!AH34 | Z18: =IF(Y18="","",SUMIF(Processamento!$AH$23:$AH$111,Y18,Processamento!$AJ$23:$AJ$111)/1000) | AA18: =+IF(Y18="","",($Z$6-Z18)/$Z$6)
B30: Recuperação de calor | X30: Recuperação de calor
C31: ="Através da recuperação de calor residual dos processos industriais térmicos apresentados poderia ser possível aproveitar até "&ROUND(Processamento!Y15/1000,0)&" MWh de energia, representando a redução de cerca de " &ROUND(Processamento!AA15/1000,2)&" toneladas de CO2. A potencial poupança económica associada à redução do consumo de energia poderia atingir os "&ROUND(Processamento!AB15,0)&" euros. (assumindo que esta energia poderia ser usada em equipamentos que usassem o mesmo vetor energético). Alerta-se para o facto de a aplicação desta medida dever ser sustentada por estudos para a avaliação da qualidade da energia residual existente." -> Através da recuperação de calor residual dos processos industriais térmicos apresentados poderia ser possível aproveitar até 278 MWh de energia, representando a redução de cerca de 61,68 toneladas de CO2. A potencial poupança económica associada à redução do consumo de energia poderia atingir os 28435 euros. (assumindo que esta energia poderia ser usada em equipamentos que usassem o mesmo vetor energético). Alerta-se para o facto de a aplicação desta medida dever ser sustentada por estudos para a avaliação da qualidade da energia residual existente. | Y31: ="Através da recuperação de calor residual dos processos industriais térmicos apresentados poderia ser possível aproveitar até "&ROUND(Processamento!BE16/1000,0)&" MWh de energia a uma temperatura baixa (até 70 °C), representando a redução de cerca de " &ROUND(Processamento!BG16/1000,2)&" toneladas de CO2. A potencial poupança económica associada à redução do consumo de energia poderia atingir os "&ROUND(Processamento!BH16,0)&" euros (assumindo que esta energia poderia ser usada em equipamentos que usassem o mesmo vetor energético). Alerta-se para o facto de a aplicação desta medida dever ser sustentada por estudos para a avaliação da qualidade da energia residual existente." -> Através da recuperação de calor residual dos processos industriais térmicos apresentados poderia ser possível aproveitar até 61 MWh de energia a uma temperatura baixa (até 70 °C), representando a redução de cerca de 12,33 toneladas de CO2. A potencial poupança económica associada à redução do consumo de energia poderia atingir os 4706 euros (assumindo que esta energia poderia ser usada em equipamentos que usassem o mesmo vetor energético). Alerta-se para o facto de a aplicação desta medida dever ser sustentada por estudos para a avaliação da qualidade da energia residual existente.

Sheet Apoio
B1: Listas
B2: Equipamentos | C2: Sim | D2: Combustível Caldeira | E2: Combustível Cogeração | F2: Combustível Forno | G2: Combustível Queimador (Dedicado a estufas ou banhos térmicos) | H2: Unidades combustível | I2: Unidades tarifa | J2: Consumo por fábrica
B3: Forno | C3: Não | D3: Biometano | E3: Biometano | F3: Biometano | G3: Biometano | H3: kWh/ano | I3: €/kWh | J3: Consumo por equipamento | L3: Combustível Alternativo | M3: PCI (GJ/ton) | N3: PCI (MJ/kg) | O3: Massa Volúmica (kg/m3) | P3: kWh/Ton | Q3: kWh/m3 | R3: kwh | S3: Fator Emissão (kgCO2e/GJ) | T3: Fator Emissão (kgCO2e/kWh) | U3: Tarifa referência(€/kWh)
B4: Caldeira | D4: Hidrogénio | E4: Hidrogénio | F4: Hidrogénio | G4: Hidrogénio | H4: ton/ano | I4: €/m3 | P4: Ton/ano | Q4: m3/ano | R4: kWh/ano
B5: Cogeração | D5: Biomassa | E5: Biomassa | F5: Biomassa | G5: Biomassa | H5: m3/ano | I5: €/ton | P5: €/ton | Q5: €/m3 | R5: €/kWh
B6: Queimador (Dedicado a estufas ou banhos térmicos) | D6: Eletricidade | E6: Gás Natural | F6: Eletricidade | G6: Gás Natural | L6: Biometano | N6: 48 | O6: 0.7 | P6: 13333.3 | Q6: 9.3333 | R6: 1 | S6: 11.11 | T6: 0.039996 | U6: 0.122
D7: Gás Natural | E7: GPL | F7: Gás Natural | G7: GPL | L7: Hidrogénio | N7: 120 | O7: 0.0899 | P7: 33333.3 | Q7: 2.9967 | R7: 1 | S7: 0 | T7: 0 | U7: =6.5/(N7/3.6) -> 0.195
D8: GPL | E8: Nafta | F8: GPL | G8: Nafta | L8: Biomassa | N8: 17.5 | O8: - | P8: =17.5/3.6*1000 -> 4861.1111 | Q8: - | R8: 1 | S8: 0 | T8: 0 | U8: 0.010286
D9: Nafta | E9: Gasóleo | F9: Nafta | G9: Gasóleo | L9: GN + Biometano 50 % | N9: 46.5 | O9: 0.77 | P9: 12916.7 | Q9: 9.9458 | R9: 1 | S9: 30.48 | T9: 0.109728 | U9: =+U13*0.5+U6*0.5 -> 0.09975
D10: Gasóleo | E10: Fuelóleo | F10: Gasóleo | G10: Fuelóleo | L10: Eletricidade | N10: - | O10: - | P10: - | Q10: - | R10: 1 | S10: 41.94 | T10: 0.151 | U10: 0.12556
D11: Fuelóleo | E11: Coque de Petroleo | F11: Fuelóleo | G11: Coque de Petroleo | L11: GN + H2 20 % | N11: 66 | O11: 0.493 | P11: 18333.3 | Q11: 9.0383 | R11: 1 | S11: 52.27 | T11: 0.188172 | U11: =+U13*0.8+U7*0.2 -> 0.101
D12: Coque de Petroleo | E12: Resíduos Industriais | F12: Coque de Petroleo | G12: Resíduos Industriais | L12: GN + H2 10 % | N12: 65 | O12: 0.546 | P12: 18055.6 | Q12: 9.8583 | R12: 1 | S12: 54.52 | T12: 0.1962612 | U12: =+U13*0.9+U7*0.1 -> 0.08925
D13: Resíduos Industriais | F13: Resíduos Industriais | L13: Gás Natural | N13: 45 | O13: 0.84 | P13: 12500 | Q13: 10.5 | R13: 1 | S13: 56.402 | T13: =+S13*0.0036 -> 0.2030472 | U13: 0.0775
L14: GPL | M14: 48.45 | N14: 46.4 | O14: 2.43 | P14: 12888.9 | Q14: 31.32 | R14: 1 | S14: 63.1049 | T14: =S14*0.0036 -> 0.22717764 | U14: =1.408/(N14/3.6) -> 0.10924138
L15: Nafta | N15: 44.4 | O15: 680 | P15: 12333.3 | Q15: 8386.6667 | R15: 1 | S15: 73.6 | T15: 0.26496 | U15: 0.05595
L16: Gasóleo | N16: 42.7 | O16: 837 | P16: 11861.1 | Q16: 9927.75 | R16: 1 | S16: 74.1 | T16: =+S16*0.0036 -> 0.26676 | U16: 0.16116
L17: Fuelóleo | M17: 40.28 | N17: 41.9 | O17: 944 | P17: 11638.9 | Q17: 10987.111 | R17: 1 | S17: 78.6 | T17: 0.28296 | U17: 0.10323
L18: Coque de Petroleo | M18: 32.2 | N18: 32.5 | O18: 800 | P18: 9027.8 | Q18: 7222.2222 | R18: 1 | S18: 93.6 | T18: 0.33696 | U18: 0.039877
L19: Resíduos Industriais | N19: 18.5 | O19: 200 | P19: 5138.9 | Q19: 1027.7778 | R19: 1 | S19: 144.9 | T19: 0.52164
L21: Equipamento | M21: Combustível | N21: Média
L22: Forno | M22: Biometano | N22: 82.5
L23: Forno | M23: Hidrogénio | N23: 82.5
L24: Forno | M24: Biomassa | N24: 82.5
L25: Forno | M25: GN + Biometano 50 % | N25: 82.5
L26: Forno | M26: Eletricidade | N26: 89.5
L27: Forno | M27: GN + H2 20 % | N27: 82.5
L28: Forno | M28: GN + H2 10 % | N28: 82.5
L29: Forno | M29: Gás Natural | N29: 82.5
L30: Forno | M30: GPL | N30: 82.5
L31: Forno | M31: Nafta | N31: 72.5
L32: Forno | M32: Gasóleo | N32: 72.5
L33: Forno | M33: Fuelóleo | N33: 72.5
... L35: Forno | M35: Resíduos Industriais | N35: 67.5
L37: Equipamento | M37: Combustível | N37: Média
L38: Caldeira | M38: Biometano | N38: 85
L39: Caldeira | M39: Hidrogénio | N39: 85
L40: Caldeira | M40: Biomassa | N40: 85
L41: Caldeira | M41: GN + Biometano 50 % | N41: 85
L42: Caldeira | M42: Eletricidade | N42: 97
L43: Caldeira | M43: GN + H2 20 % | N43: 85
...

Sheet Sheet1
E3: Quantidade | F3: PCI [kWh/kg] | G3: Densidade [kg/m3] | H3: Fator emissão [kgCO2/kWh] | I3: Fator emissão [kgCO2/m3]
D4: Gás natural | E4: 0.8 | F4: =45/3.6 -> 12.5 | G4: 0.84 | H4: 0.20305 | I4: =+H4*F4*G4 -> 2.132025
D5: H2 | E5: 0.2 | F5: =120/3.6 -> 33.333333 | G5: 0.0899 | H5: 0 | I5: =+H5*F5*G5 -> 0
D6: Mistura | F6: =+((F4*G4)*E4+(F5*G5)*E5)/G6 -> 13.04289 | G6: =+$E$4*G4+E$5*G5 -> 0.68998 | H6: =+I6/G6/F6 -> 0.18952737 | I6: =+I4*E4+I5*E5 -> 1.70562
B7: =+E4*H4+E5*H5 -> 0.16244
G10: =+H6/H4 -> 0.93340247
